def test_raise_python_exception() -> int:
    raise ValueError("This is a Python exception")
